Workbook
Name \a: #REF!
Name \a: #REF!
Name \b: #REF!
Name \b: #REF!
Name Adv_FifteenHundred: #REF!
Name Adv_FifteenHundred: #REF!
Name Annual_Vol: #REF!
Name Buttons: #REF!
Name Buttons: #REF!
Name Cell_Qty: #REF!
Name Cell_Qty_on_MBC: #REF!
Name Chart: #REF!
Name Co_A: #REF!
Name Co_A: #REF!
Name Co_B: #REF!
Name Co_B: #REF!
Name Co_C: #REF!
Name Co_C: #REF!
Name Co_D: #REF!
Name Co_D: #REF!
Name CO_Dur: #REF!
Name Co_E: #REF!
Name Co_E: #REF!
Name Co_F: #REF!
Name Co_F: #REF!
Name CO_Freq: #REF!
Name CO_Percent: #REF!
Name CO_Time_per_Cycle: #REF!
Name Cons_Chg_Interv: #REF!
Name Cons_Dur: #REF!
Name Cons_Freq: #REF!
Name Cons_Percent: #REF!
Name Cons_Time_per_Cycle: #REF!
Name Copy: #REF!
Name Copy: #REF!
Name Copy_Range: #REF!
Name Copy_Range: #REF!
Name Cost_per_Machine: #REF!
Name Criteria_MI: #REF!
Name Criteria_MI: #REF!
Name Cum_FTQ_Loss: #REF!
Name Cycle_Time: #REF!
Name Daily_Vol: #REF!
Name Database_MI: #REF!
Name Database_MI: #REF!
Name Design_Cycle_Time_on_MB: #REF!
Name Design_Thruput_Rate: #REF!
Name Downstream_Loss_Contribution: #REF!
Name DS_CLTQ: #REF!
Name Eff_Mach_CT: #REF!
Name Eff_Mach_CT_Sys: #REF!
Name Eff_Sys_Thru: #REF!
Name End: #REF!
Name End: #REF!
Name EST: #REF!
Name Fifteenhundred: #REF!
Name Fifteenhundred: #REF!
Name Final_Range: #REF!
Name Final_Range: #REF!
Name FTQ_Loss: #REF!

Sheet TOTAL values GCSD
B1: SUMMARY
B3: PART NUMBER | C3: GCSD | D3: ADJ. | E3: PLANT STANDARD
B4: TOTAL TIME | C4: (min) | D4: % | E4: (min)
B5: PER HARNESS
B6: CUTTING | C6: =(CUTTING!J685)/60 -> 3.6935524 | D6: 1.443 | E6: =C6*D6 -> 5.3297961 | M6: Wires number :
B7: EU wire marking penalty | C7: =(CUTTING!L685-CUTTING!J685)/60 -> 0 | D7: 1.443 | E7: =C7*D7 -> 0 | M7: Cutting | N7: =ROUND(M19+M20+M21,3) -> 7.001
B8: TUBE CUTTING | C8: =(CUTTING!L687)/60 -> 1.1582167 | D8: 1.443 | E8: =C8*D8 -> 1.6713067 | M8: Lead Prep | N8: =ROUND(M22,3) -> 21.707
B9: EU- LEAD - PREP | C9: =(('LEAD PREP'!K347)/60)+(CUTTING!L689/60) -> 19.074667 | D9: 1.138 | E9: =C9*D9 -> 21.706971 | M9: R2* Lead Prep | N9: =ROUND(M23,3) -> 2.731
B10: FINAL ASSEMBLY | C10: =(('FA Conns and wires'!T112+'FA Taping'!J81+'FA Miscellaneos'!K141)/60+('LEAD PREP'!K349+'LEAD PREP FA'!K340)/60) -> 59.401187 | D10: 1.078 | E10: =C10*D10 -> 64.03448 | M10: Assembly | N10: =ROUND(M24+M25+M26,3) -> 74.478
B11: FA TEST | C11: =('FA Miscellaneos'!K142)/60 -> 6.7641 | D11: 1.078 | E11: =C11*D11 -> 7.2916998 | M11: TOTAL | N11: =ROUND(N10+N8+N7+N9,3) -> 105.917
B12: FINAL ASSEMBLY PACKING | C12: =(('FA Taping'!J82)+('FA Miscellaneos'!K143))/60 -> 2.92375 | D12: 1.078 | E12: =C12*D12 -> 3.1518025
B13: TOTAL | C13: =SUM(C6:C12) -> 93.015473 | E13: =SUM(E6:E12) -> 103.18606
J14: TOTAL SUMMARY + ANTENNA + OPTICAL FIBER + IGNITION CABLE + HIGH VOLTAGE
B15: HIGH VOLTAGE
B16: PART NUMBER | C16: GCSD | D16: ADJ. | E16: PLANT STANDARD | J16: PART NUMBER | K16: GCSD | L16: ADJ. | M16: PLANT STANDARD
B17: TOTAL TIME | C17: (min) | D17: % | E17: (min) | J17: TOTAL TIME | K17: (min) | L17: % | M17: (min)
B18: PER HARNESS | J18: PER HARNESS
B19: CUTTING | C19: =(CUTTING!J685)/60 -> 3.6935524 | D19: 1.443 | E19: =C19*D19 -> 5.3297961 | J19: CUTTING | K19: =C6 -> 3.6935524 | L19: 1.443 | M19: =K19*L19 -> 5.3297961
B20: TUBE CUTTING | C20: =(CUTTING!L687)/60 -> 1.1582167 | D20: 1.443 | E20: =C20*D20 -> 1.6713067 | J20: EU wire marking penalty | K20: =(CUTTING!L685-CUTTING!J685)/60 -> 0 | L20: 1.443 | M20: =K20*L20 -> 0
B21: LEAD - PREP | C21: =C9 -> 19.074667 | D21: 1.138 | E21: =C21*D21 -> 21.706971 | J21: TUBE CUTTING | K21: =(CUTTING!L687)/60 -> 1.1582167 | L21: 1.443 | M21: =K21*L21 -> 1.6713067
B22: FINAL ASSEMBLY | C22: =('High Voltage'!K111+'FA Conns and wires'!T112+'FA Taping'!J81+'FA Miscellaneos'!K141)/60 -> 58.601188 | D22: 1.078 | E22: =C22*D22 -> 63.17208 | J22: EU- LEAD - PREP | K22: =C9 -> 19.074667 | L22: 1.138 | M22: =K22*L22 -> 21.706971
B23: TOTAL | C23: =SUM(C19:C22) -> 82.527623 | E23: =SUM(E19:E22) -> 91.880154 | J23: EU - R2* LEAD PREP | K23: ='LEAD PREP'!K352/60 -> 2.4 | L23: 1.138 | M23: =K23*L23 -> 2.7312
J24: FINAL ASSEMBLY | K24: =C10 -> 59.401187 | L24: 1.078 | M24: =K24*L24 -> 64.03448
J25: FA TEST | K25: =('FA Miscellaneos'!K142)/60 -> 6.7641 | L25: 1.078 | M25: =K25*L25 -> 7.2916998
J26: FINAL ASSEMBLY PACKING | K26: =(('FA Taping'!J82)+('FA Miscellaneos'!K143))/60 -> 2.92375 | L26: 1.078 | M26: =K26*L26 -> 3.1518025
J27: TOTAL | K27: =SUM(K19:K26) -> 95.415473 | M27: =SUM(M19:M26) -> 105.91726

Sheet CUTTING
A2: Comments | B2: Machine Vendor | C2: Machine | D2: Min Gage | E2: Max Gage | F2: Min Length | G2: Max Length | H2: Global Sec/ Pc | I2: TOTAL Qty Leads | J2: SUB TOTAL | K2: Qty Marked Leads | L2: TOTAL TIME
A3: Drain Wire Automatic Cutting | B3: Drain Wire Cutter | C3: Schleuniger OC3950 | D3: 0.3 | E3: 5 | F3: 50 | G3: 1000 | H3: 1.2301 | J3: =+I3*H3 -> 0 | L3: =J3 -> 0 | M3: Automatic
D4: 0.3 | E4: 5 | F4: 1001 | G4: 1500 | H4: 1.7051 | J4: =+I4*H4 -> 0 | L4: =J4 -> 0 | M4: Automatic
D5: 0.3 | E5: 5 | F5: 1501 | G5: 2000 | H5: 2.2101 | J5: =+I5*H5 -> 0 | L5: =J5 -> 0 | M5: Automatic
D6: 0.3 | E6: 5 | F6: 2001 | G6: 2500 | H6: 2.7451 | J6: =+I6*H6 -> 0 | L6: =J6 -> 0 | M6: Automatic
D7: 0.3 | E7: 5 | F7: 2501 | G7: 3000 | H7: 3.3101 | J7: =+I7*H7 -> 0 | L7: =J7 -> 0 | M7: Automatic
D8: 0.3 | E8: 5 | F8: 3001 | G8: 3500 | H8: 3.9051 | J8: =+I8*H8 -> 0 | L8: =J8 -> 0 | M8: Automatic
D9: 0.3 | E9: 5 | F9: 3501 | G9: 4000 | H9: 4.5301 | J9: =+I9*H9 -> 0 | L9: =J9 -> 0 | M9: Automatic
D10: 0.3 | E10: 5 | F10: 4001 | G10: 4500 | H10: 5.1851 | J10: =+I10*H10 -> 0 | L10: =J10 -> 0 | M10: Automatic
D11: 0.3 | E11: 5 | F11: 4501 | G11: 5000 | H11: 5.8701 | J11: =+I11*H11 -> 0 | L11: =J11 -> 0 | M11: Automatic
D12: 0.3 | E12: 5 | F12: 5001 | G12: 5500 | H12: 6.5851 | J12: =+I12*H12 -> 0 | L12: =J12 -> 0 | M12: Automatic
D13: 0.3 | E13: 5 | F13: 5501 | G13: 6000 | H13: 7.3051 | J13: =+I13*H13 -> 0 | L13: =J13 -> 0 | M13: Automatic
D14: 0.3 | E14: 5 | F14: 6001 | G14: 6500 | H14: 8.0251 | J14: =+I14*H14 -> 0 | L14: =J14 -> 0 | M14: Automatic
D15: 0.3 | E15: 5 | F15: 6501 | G15: 7000 | H15: 8.7451 | J15: =+I15*H15 -> 0 | L15: =J15 -> 0 | M15: Automatic
... D21: 0.3 | E21: 5 | F21: 9501 | G21: 10000 | H21: 13.0651 | J21: =+I21*H21 -> 0 | L21: =J21 -> 0 | M21: Automatic
J22: =+I22*H22 -> 0 | L22: =J22 -> 0
J23: =+I23*H23 -> 0 | L23: =J23 -> 0
J24: =+I24*H24 -> 0 | L24: =J24 -> 0
J25: =+I25*H25 -> 0 | L25: =J25 -> 0
A26: cut coaxial twisted twin cables and multiconductor wires FLEX RAY ETHERNET | B26: Multi & Coaxial Cutter | C26: Schleuniger PS 9550 / 9480 | D26: 0.2 | E26: 10 | F26: 60 | G26: 100 | H26: 4.16 | J26: =+I26*H26 -> 0 | L26: =IF(K26>I26,"ERROR",(K26*H26)*0.1+J26) -> 0 | M26: Automatic
D27: 0.2 | E27: 10 | F27: 101 | G27: 1000 | H27: 4.16 | I27: 1 | J27: =+I27*H27 -> 4.16 | L27: =IF(K27>I27,"ERROR",(K27*H27)*0.1+J27) -> 4.16 | M27: Automatic
D28: 0.2 | E28: 10 | F28: 1001 | G28: 2000 | H28: 5.43 | J28: =+I28*H28 -> 0 | L28: =IF(K28>I28,"ERROR",(K28*H28)*0.15+J28) -> 0 | M28: Automatic
D29: 0.2 | E29: 10 | F29: 2001 | G29: 3000 | H29: 6.6 | J29: =+I29*H29 -> 0 | L29: =IF(K29>I29,"ERROR",(K29*H29)*0.2+J29) -> 0 | M29: Automatic
D30: 0.2 | E30: 10 | F30: 3001 | G30: 4000 | H30: 7.74 | J30: =+I30*H30 -> 0 | L30: =IF(K30>I30,"ERROR",(K30*H30)*0.25+J30) -> 0 | M30: Automatic
D31: 0.2 | E31: 10 | F31: 4001 | G31: 5000 | H31: 8.9 | J31: =+I31*H31 -> 0 | L31: =IF(K31>I31,"ERROR",(K31*H31)*0.3+J31) -> 0 | M31: Automatic
D32: 0.2 | E32: 10 | F32: 5001 | G32: 6000 | H32: 9.99 | J32: =+I32*H32 -> 0 | L32: =IF(K32>I32,"ERROR",(K32*H32)*0.3+J32) -> 0 | M32: Automatic
D33: 0.2 | E33: 10 | F33: 6001 | G33: 7000 | H33: 10.68 | J33: =+I33*H33 -> 0 | L33: =IF(K33>I33,"ERROR",(K33*H33)*0.3+J33) -> 0 | M33: Automatic
D34: 0.2 | E34: 10 | F34: 7001 | G34: 8000 | H34: 12.37 | J34: =+I34*H34 -> 0 | L34: =IF(K34>I34,"ERROR",(K34*H34)*0.3+J34) -> 0 | M34: Automatic
D35: 0.2 | E35: 10 | F35: 8001 | G35: 9000 | H35: 13.01 | J35: =+I35*H35 -> 0 | L35: =IF(K35>I35,"ERROR",(K35*H35)*0.3+J35) -> 0 | M35: Automatic
D36: 0.2 | E36: 10 | F36: 9001 | G36: 10000 | H36: 14.68 | J36: =+I36*H36 -> 0 | L36: =IF(K36>I36,"ERROR",(K36*H36)*0.3+J36) -> 0 | M36: Automatic
D37: 0.2 | E37: 10 | F37: 10001 | G37: 11000 | H37: 15.35 | J37: =+I37*H37 -> 0 | L37: =IF(K37>I37,"ERROR",(K37*H37)*0.3+J37) -> 0 | M37: Automatic
D38: 0.2 | E38: 10 | F38: 11001 | G38: 12000 | H38: 15.96 | J38: =+I38*H38 -> 0 | L38: =IF(K38>I38,"ERROR",(K38*H38)*0.3+J38) -> 0 | M38: Automatic
D39: 0.2 | E39: 10 | F39: 12001 | G39: 13000 | H39: 16.58 | J39: =+I39*H39 -> 0 | L39: =IF(K39>I39,"ERROR",(K39*H39)*0.3+J39) -> 0 | M39: Automatic
D40: 0.2 | E40: 10 | F40: 13001 | G40: 14000 | H40: 17.22 | J40: =+I40*H40 -> 0 | L40: =IF(K40>I40,"ERROR",(K40*H40)*0.3+J40) -> 0 | M40: Automatic
J41: =+I41*H41 -> 0 | L41: =IF(K41>I41,"ERROR",(K41*H41)*0.3+J41) -> 0
J42: =+I42*H42 -> 0 | L42: =IF(K42>I42,"ERROR",(K42*H42)*0.3+J42) -> 0
J43: =+I43*H43 -> 0 | L43: =IF(K43>I43,"ERROR",(K43*H43)*0.3+J43) -> 0
J44: =+I44*H44 -> 0 | L44: =IF(K44>I44,"ERROR",(K44*H44)*0.3+J44) -> 0
A45: cut heavy gage cables | B45: Heavy Gage Cutter | C45: Schleuniger PS9550 | D45: 6 | E45: 10 | F45: 60 | G45: 100 | H45: 3.34 | J45: =+I45*H45 -> 0 | L45: =IF(K45>I45,"ERROR",(K45*H45)*0.1+J45) -> 0 | M45: Automatic
D46: 6 | E46: 10 | F46: 101 | G46: 1000 | H46: 3.34 | I46: 2 | J46: =+I46*H46 -> 6.68 | L46: =IF(K46>I46,"ERROR",(K46*H46)*0.1+J46) -> 6.68 | M46: Automatic
...

Sheet LEAD PREP
A1: LEAD PREP PROCESS
A2: SEAL APPLICATIONS (Including Grommet Pass through) | B2: COMMENTS | C2: Machine | D2: Multicond? | E2: Min Gage | F2: Max Gage | H2: Global Sec/ Pc | I2: Location LP/FA | J2: QTY | K2: TOTAL
A3: APPLY SEAL | B3: apply seal in a normal cable | C3: Seal Station / per application | E3: 0.13 | F3: 8 | H3: 5.26 | I3: LP | J3: 1 | K3: =+J3*H3 -> 5.26 | L3: LP | M3: Automatic
B4: apply seals in multiconductor cable (to be applied also to apply seal to subassiemblies) | D4: Y | E4: 0.13 | F4: 8 | H4: 6 | I4: LP | J4: 2 | K4: =+J4*H4 -> 12 | L4: FA | M4: Automatic
A5: APPLY / PLUG SEAL / CAVITY PLUG TO CONNECTOR | B5: Insert cavity plugs in connectors | C5: Seal Station / per application (masks or small devices to support can be used) | H5: 4 | I5: LP | J5: 30 | K5: =+J5*H5 -> 120 | M5: R2*
A6: PERFORATE CONNECTOR AND CONNECTOR COMPONENTS | B6: punch holes in connector / seal / perforate plugs of connector cover | C6: Newmatic punch press | H6: 9 | I6: LP | K6: =+J6*H6 -> 0 | M6: Semi-automatic
A7: PERFORATE BOOT | B7: Perforate connector boot | C7: Newmatic punch press | H7: 12.67 | I7: LP | K7: =+J7*H7 -> 0 | M7: Automatic
A8: APPLY BACKSHELL TO CONN | B8: apply backshell to connector | C8: manual tool | H8: 10.4 | I8: LP | K8: =+J8*H8 -> 0 | M8: Semi-automatic
A9: SEAL OVER CONN | B9: apply seal over connector | C9: Seal Inserter for Conn seal | H9: 9.75 | I9: LP | K9: =+J9*H9 -> 0 | M9: Automatic
A10: APPLY MIXED FLUIDS | B10: mix up fluids into grommet | C10: Two Fluids machine | H10: 17.4 | I10: LP | K10: =+J10*H10 -> 0 | M10: Automatic
A11: INSRT LEADS IN GROM | B11: grommets boots & sleeves over branch | C11: Grommet Spreader (4 bill) | H11: 28.08 | I11: LP | K11: =+J11*H11 -> 0 | M11: Manual
A12: JOIN CABLE TIE WITH BODY CLIP | B12: per component application | C12: manual station to join two seperate DPN / APN | H12: 3 | I12: LP | J12: 8 | K12: =+J12*H12 -> 24 | M12: R2*
K13: =+J13*H13 -> 0
K14: =+J14*H14 -> 0
A16: SEALING (including LMX, RAYBLOCK, coldmelt) | B16: COMMENTS | C16: Machine Vendor | D16: Min Gage | E16: Max Gage | F16: Min Length | G16: Max Length | H16: Global Sec/ Pc | I16: Location LP/FA | J16: QTY | K16: Total
A17: Heat Shrink on term. including automatic cooling (performed by the shrinking machine) | B17: heat shrink over terminal Cooling of the tubes shrinked over ring terminal and over the cable (average time, taking into consideration set of subs is cooled at the same time) | C17: IR 1891Shuttle - Air, Slide Toaster, etc. | D17: 0 mm² | E17: 30mm² | H17: 13.5 | I17: LP | J17: 5 | K17: =+J17*H17 -> 67.5 | M17: Manual
D18: 31 mm² | E18: 120mm² | H18: 24 | I18: LP | J18: 2 | K18: =+J18*H18 -> 48 | M18: Automatic
A19: HEAT SHRINK | B19: heat shrink over cable / multiconductor cable including drain wire (often on drain wire of multiconductor where diameter of tubes are smaller or equal to 6 mm) | C19: Heat Shrink station | F19: 0 | G19: 80 | H19: 15.6 | I19: LP | J19: 1 | K19: =+J19*H19 -> 15.6 | M19: Automatic
F20: 81 | G20: 160 | H20: 18.61 | I20: LP | K20: =+J20*H20 -> 0 | M20: Automatic
A21: HEAT SHRINK OVER CONNECTOR to be used also for Heat shrink sleeve/tube over hose | B21: per connector / hose | C21: Raychem IR 03/15 & R.Semiautom./ FLS MK2 'Speed 40-90 / Temp. 100ºC | H21: 49.13 | I21: LP | K21: =+J21*H21 -> 0 | M21: Manual
B22: per hot melt (additional glue / sealing) application - to be used also for splices and multiconductors (plastic ferrules application) | F22: 1 | G22: 99999 | H22: 3.73 | I22: LP | K22: =+J22*H22 -> 0 | M22: Automatic
A23: Sealing of strands from ring terminal | B23: Cover crimped strands from a ring terminal with sealing to protect them against environment (when customer request) | C23: Heat Gun | H23: 65 | I23: LP | K23: =+J23*H23 -> 0 | M23: Manual
K24: =+J24*H24 -> 0
A25: HEAT SHRINK | B25: antena heat shrinking on metal terminal | F25: 2 | G25: 99999 | H25: 20.74 | I25: LP | K25: =+J25*H25 -> 0 | M25: Manual
A26: HEAT SHRINK CD SLEEVE | B26: shrinking sleeve with cadmium solder | C26: Heat shrink Cd sleeve Station | H26: 46.6 | I26: LP | K26: =+J26*H26 -> 0 | M26: Manual
A27: HEAT SHRINK GROMMET | B27: shrink grommet over a harness branch | C27: Heat shrink grommet Station | H27: 69.82 | I27: LP | K27: =+J27*H27 -> 0 | M27: Automatic
A28: HEAT SHRINK TUBE END | B28: Apply heat to seal the Watter tube end | C28: Heat shrink tube end Station | H28: 4.07 | I28: LP | K28: =+J28*H28 -> 0 | M28: Manual
A29: COLD MELT / BUTYL | B29: Get and apply Coldmelt / Butyl Strips - press each piece with a plier/press - PER PIECE | C29: Use press for more than 5 strips If press is not used, pliers must be use always | D29: up to 4 pcs | H29: 33.02 | I29: LP | K29: =+J29*H29 -> 0 | M29: Manual
D30: 5 to 9 pcs | H30: 49.53 | I30: LP | K30: =+J30*H30 -> 0 | M30: Manual
D31: 10 or more pcs | H31: 66.04 | I31: LP | K31: =+J31*H31 -> 0 | M31: Manual
B32: Form the Coldmelt and position sleeve | C32: Manual work | H32: 28.67 | I32: LP | K32: =+J32*H32 -> 0 | M32: Manual
B33: Shrinking of the tube over sealing branch Load/Cycle/Unload | C33: DSG Canusa Sealman 70 | D33: 3 to 4 pcs | H33: 72 | I33: LP | K33: =+J33*H33 -> 0 | M33: Manual
D34: 5 to 9 pcs | H34: 187 | I34: LP | K34: =+J34*H34 -> 0 | M34: Manual
D35: 10 or more pcs | H35: 225 | I35: LP | K35: =+J35*H35 -> 0 | M35: Manual
A36: TEROSTAT PREPARATION | B36: terostat preparation (including weight) | D36: Portion weighted and ready to use | H36: 9.04 | I36: LP | K36: =+J36*H36 -> 0 | M36: R2*
B37: Slice terostat when provided in block (if applies) AP REGION ONLY | C37: Gilotinue | H37: 6.916 | I37: LP | K37: =+J37*H37 -> 0 | M37: R2*
B38: Remove protection and make portion of terostat flat (if applies) AP REGION ONLY | C38: Manual work | H38: 11.78 | I38: LP | K38: =+J38*H38 -> 0 | M38: R2*
A39: BATTERIES | B39: COMMENTS | C39: Machine | D39: Special Component | H39: Global Sec/ Pc | I39: Location LP/FA | J39: QTY | K39: Total
A40: BATTERY COVER | B40: battery cover | C40: batt cover & Bolt Station | H40: 6 | I40: LP | K40: =+J40*H40 -> 0 | M40: Automatic
A41: BATTERY COVER & BOLT | B41: battery cover & bolt | C41: batt cover & bolt Station | H41: 10 | I41: LP | K41: =+J41*H41 -> 0 | M41: Automatic
...

Sheet LEAD PREP FA
A1: LEAD PREP PROCESS
A2: SEAL APPLICATIONS (Including Grommet Pass through) | B2: COMMENTS | C2: Machine | D2: Multicond? | E2: Min Gage | F2: Max Gage | H2: Global Sec/ Pc | I2: Location LP/FA | J2: QTY | K2: TOTAL
A3: APPLY SEAL | B3: apply seal in a normal cable | C3: Seal Station / per application | E3: 0.13 | F3: 8 | H3: 5.26 | I3: FA | K3: =+J3*H3 -> 0 | L3: LP | M3: Automatic
B4: apply seals in multiconductor cable (to be applied also to apply seal to subassiemblies) | D4: Y | E4: 0.13 | F4: 8 | H4: 6 | I4: FA | K4: =+J4*H4 -> 0 | L4: FA | M4: Automatic
A5: APPLY / PLUG SEAL / CAVITY PLUG TO CONNECTOR | B5: Insert cavity plugs in connectors | C5: Seal Station / per application (masks or small devices to support can be used) | H5: 4 | I5: FA | J5: 12 | K5: =+J5*H5 -> 48
A6: PERFORATE CONNECTOR AND CONNECTOR COMPONENTS | B6: punch holes in connector / seal / perforate plugs of connector cover | C6: Newmatic punch press | H6: 9 | I6: FA | K6: =+J6*H6 -> 0 | M6: Semi-automatic
A7: PERFORATE BOOT | B7: Perforate connector boot | C7: Newmatic punch press | H7: 12.67 | I7: FA | K7: =+J7*H7 -> 0 | M7: Automatic
A8: APPLY BACKSHELL TO CONN | B8: apply backshell to connector | C8: manual tool | H8: 10.4 | I8: FA | K8: =+J8*H8 -> 0 | M8: Semi-automatic
A9: SEAL OVER CONN | B9: apply seal over connector | C9: Seal Inserter for Conn seal | H9: 9.75 | I9: FA | K9: =+J9*H9 -> 0 | M9: Automatic
A10: APPLY MIXED FLUIDS | B10: mix up fluids into grommet | C10: Two Fluids machine | H10: 17.4 | I10: FA | K10: =+J10*H10 -> 0 | M10: Automatic
A11: INSRT LEADS IN GROM | B11: grommets boots & sleeves over branch | C11: Grommet Spreader (4 bill) | H11: 28.08 | I11: FA | K11: =+J11*H11 -> 0 | M11: Manual
A12: JOIN CABLE TIE WITH BODY CLIP | B12: per component application | C12: manual station to join two seperate DPN / APN | H12: 3 | I12: FA | K12: =+J12*H12 -> 0
K13: =+J13*H13 -> 0
K14: =+J14*H14 -> 0
A16: SEALING (including LMX, RAYBLOCK, coldmelt) | B16: COMMENTS | C16: Machine Vendor | D16: Min Gage | E16: Max Gage | F16: Min Length | G16: Max Length | H16: Global Sec/ Pc | I16: Location LP/FA | J16: QTY | K16: Total
A17: Heat Shrink on term. including automatic cooling (performed by the shrinking machine) | B17: heat shrink over terminal Cooling of the tubes shrinked over ring terminal and over the cable (average time, taking into consideration set of subs is cooled at the same time) | C17: IR 1891Shuttle - Air, Slide Toaster, etc. | D17: 0 mm² | E17: 30mm² | H17: 13.5 | I17: FA | K17: =+J17*H17 -> 0 | M17: Manual
D18: 31 mm² | E18: 120mm² | H18: 24 | I18: FA | K18: =+J18*H18 -> 0 | M18: Automatic
A19: HEAT SHRINK | B19: heat shrink over cable / multiconductor cable including drain wire (often on drain wire of multiconductor where diameter of tubes are smaller or equal to 6 mm) | C19: Heat Shrink station | F19: 0 | G19: 80 | H19: 15.6 | I19: FA | K19: =+J19*H19 -> 0 | M19: Automatic
F20: 81 | G20: 160 | H20: 18.61 | I20: FA | K20: =+J20*H20 -> 0 | M20: Automatic
A21: HEAT SHRINK OVER CONNECTOR to be used also for Heat shrink sleeve/tube over hose | B21: per connector / hose | C21: Raychem IR 03/15 & R.Semiautom./ FLS MK2 'Speed 40-90 / Temp. 100ºC | H21: 49.13 | I21: FA | K21: =+J21*H21 -> 0 | M21: Manual
B22: per hot melt (additional glue / sealing) application - to be used also for splices and multiconductors (plastic ferrules application) | F22: 1 | G22: 99999 | H22: 3.73 | I22: FA | K22: =+J22*H22 -> 0 | M22: Automatic
A23: Sealing of strands from ring terminal | B23: Cover crimped strands from a ring terminal with sealing to protect them against environment (when customer request) | C23: Heat Gun | H23: 65 | I23: FA | K23: =+J23*H23 -> 0 | M23: Manual
K24: =+J24*H24 -> 0
A25: HEAT SHRINK | B25: antena heat shrinking on metal terminal | F25: 2 | G25: 99999 | H25: 20.74 | I25: FA | K25: =+J25*H25 -> 0 | M25: Manual
A26: HEAT SHRINK CD SLEEVE | B26: shrinking sleeve with cadmium solder | C26: Heat shrink Cd sleeve Station | H26: 46.6 | I26: FA | K26: =+J26*H26 -> 0 | M26: Manual
A27: HEAT SHRINK GROMMET | B27: shrink grommet over a harness branch | C27: Heat shrink grommet Station | H27: 69.82 | I27: FA | K27: =+J27*H27 -> 0 | M27: Automatic
A28: HEAT SHRINK TUBE END | B28: Apply heat to seal the Watter tube end | C28: Heat shrink tube end Station | H28: 4.07 | I28: FA | K28: =+J28*H28 -> 0 | M28: Manual
A29: COLD MELT / BUTYL | B29: Get and apply Coldmelt / Butyl Strips - press each piece with a plier/press - PER PIECE | C29: Use press for more than 5 strips If press is not used, pliers must be use always | D29: up to 4 pcs | H29: 33.02 | I29: FA | K29: =+J29*H29 -> 0 | M29: Manual
D30: 5 to 9 pcs | H30: 49.53 | I30: FA | K30: =+J30*H30 -> 0 | M30: Manual
D31: 10 or more pcs | H31: 66.04 | I31: FA | K31: =+J31*H31 -> 0 | M31: Manual
B32: Form the Coldmelt and position sleeve | C32: Manual work | H32: 28.67 | I32: FA | K32: =+J32*H32 -> 0 | M32: Manual
B33: Shrinking of the tube over sealing branch Load/Cycle/Unload | C33: DSG Canusa Sealman 70 | D33: 3 to 4 pcs | H33: 72 | I33: FA | K33: =+J33*H33 -> 0 | M33: Manual
D34: 5 to 9 pcs | H34: 187 | I34: FA | K34: =+J34*H34 -> 0 | M34: Manual
D35: 10 or more pcs | H35: 225 | I35: FA | K35: =+J35*H35 -> 0 | M35: Manual
A36: TEROSTAT PREPARATION | B36: terostat preparation (including weight) | D36: Portion weighted and ready to use | H36: 9.04 | I36: FA | K36: =+J36*H36 -> 0
B37: Slice terostat when provided in block (if applies) AP REGION ONLY | C37: Gilotinue | H37: 6.916 | I37: FA | K37: =+J37*H37 -> 0
B38: Remove protection and make portion of terostat flat (if applies) AP REGION ONLY | C38: Manual work | H38: 11.78 | I38: FA | K38: =+J38*H38 -> 0
A39: BATTERIES | B39: COMMENTS | C39: Machine | D39: Special Component | H39: Global Sec/ Pc | I39: Location LP/FA | J39: QTY | K39: Total
A40: BATTERY COVER | B40: battery cover | C40: batt cover & Bolt Station | H40: 6 | I40: FA | K40: =+J40*H40 -> 0 | M40: Automatic
A41: BATTERY COVER & BOLT | B41: battery cover & bolt | C41: batt cover & bolt Station | H41: 10 | I41: FA | K41: =+J41*H41 -> 0 | M41: Automatic
...

Sheet High Voltage
A1: HIGH VOLTAGE HARNESS - COAXIAL & MULITICORE CABLES
A2: NOTE FOR EU FLOW 3: Standard times by connector Supplier are available under the link: | E2: http://p04.na.delphiauto.net/04/102/cme/IndEng/GCSD/Shared%20Documents/Forms/AllItems.aspx?RootFolder=%2F04%2F102%2Fcme%2FIndEng%2FGCSD%2FShared%20Documents%2FGCSD%20Catalogue%2FHV%20catalogue%20by%20connector&InitialTabId=Ribbon%2EDocument&VisibilityContext=WSSTabPersistence
A3: CUTTING
A4: BUILD CATEGORY | B4: ACTIVITY DESCRIPTION | C4: Standard Description | D4: Clock start | E4: Clock stop | H4: GLOBAL SEC/PC | I4: UNIT | J4: Qty | K4: Total Time
A5: for cables cutting use standards for heavy gage (cutting sheet, Schleuniger MS 9600 standards)
A6: for tubes cutting use standards from cutting sheet (PVC Tube/ Sleeve Cutting or convoluted tube cutting - depending on tube type)
A8: LEAD PREP
A10: OPERATION | B10: ACTIVITY DESCRIPTION | C10: Machine Vendor | D10: Clock start | E10: Clock stop | F10: Min Length | G10: Max Length | H10: GLOBAL SEC/PC | I10: UNIT | J10: Qty | K10: Total Time
A11: Apply loose piece materials over wire | B11: Pick up and apply loose materials (covers / housings / spacers / metal rings /shrinking tubes /metalic shields / protections / ferrule) over cable or inner housing and fix with tie / stopper | C11: manual work | D11: pick up the piece | E11: put cable away | H11: 4.53 | I11: pc | K11: =+J11*H11 -> 0 | L11: Manual
A12: Apply sealing elements over wire | B12: seal + collet / grommet over cable | C12: hand tool | D12: pick up the piece | E12: put cable away | H12: 10 | I12: pc | K12: =+J12*H12 -> 0 | L12: Manual
B13: apply and close segger | C13: hand tool | D13: pick up the piece | E13: put cable away | H13: 17.4 | I13: pc | K13: =+J13*H13 -> 0 | L13: Manual
B14: gripper / 2 piece cover to the seal | C14: manual work | D14: pick up the piece | E14: put cable away | H14: 17.4 | I14: pc | K14: =+J14*H14 -> 0 | L14: Manual
A15: Apply block seal | B15: Pass throug wires into block seal | C15: manual | D15: pick up the cable | E15: put cable away | F15: 0.5 mm² | G15: 0.5 mm² | H15: 23 | I15: pc | K15: =+J15*H15 -> 0 | L15: Manual
F16: 2.5 mm² | G16: 2.5 mm² | H16: 7 | I16: pc | K16: =+J16*H16 -> 0 | L16: Manual
A17: Take out outer jacket manually | B17: Take out outer jacket of stripped cable. | C17: manual work | D17: pick up cable | E17: put cable away | F17: 150 | G17: 200 | H17: 26 | I17: pc | K17: =+J17*H17 -> 0 | L17: Manual
A18: Outer jacket stripping for coaxial cable | B18: Outer jacket stripping | C18: Schleuniger CS5500 | D18: place the cable in the machine head | E18: put cable away | F18: 0 | G18: 80 | H18: 15.3 | I18: pc | K18: =+J18*H18 -> 0 | L18: Manual
A19: Outer jacket stripping for multicore cable | B19: Cut & stripping outer jacket - aluminium foil - filler - braided shield in one step | C19: Schleuniger CS5500 | D19: place the cable in the machine head | E19: put cable away | F19: 0 | G19: 80 | H19: 19.7 | I19: pc | K19: =+J19*H19 -> 0 | L19: Manual
A20: Defoil and cut aluminium foil / cotton strip (for all shilded) | B20: Cut foil with hand tool open the foil and remove | C20: hand tool / scissors | D20: remove the outer insulation | E20: foil removed | H20: 7 | I20: pc | K20: =+J20*H20 -> 0 | L20: Manual
A21: Cut the braided shield | B21: Cut the braided shield | C21: Rittmeyer. Beri Co.Cut Shield cuting device | D21: place the cable in the tool | E21: put cable away | F21: 0 | G21: 150 | H21: 11.2 | I21: pc | K21: =+J21*H21 -> 0 | L21: Manual
F22: 151 | G22: 300 | H22: 21 | I22: pc | K22: =+J22*H22 -> 0 | L22: Manual
F23: 301 | G23: 500 | H23: 34 | I23: pc | K23: =+J23*H23 -> 0 | L23: Manual
A24: Shield and jacket processing on Coroplast 25 mm² cable | B24: Cable placement in machine’s grippers, shield opening, shield cutting, shield folding, inner jacket stripping, cable release. | C24: Komax Lambda 240 SP | D24: pick up the cable | E24: put cable away | F24: 8 | G24: 100 | H24: 22.4 | I24: pc | K24: =+J24*H24 -> 0
A25: Fold back and fix braided shield with tape | B25: time include to pick up wire, fold back braided shield using the tool, assembly wire to holder, get tape and make spot on shield according to layout, cut tape and remove the wire NOTE: Mspec M4827009 5mm width | C25: positioning tool | D25: pick up the cable | E25: put cable away | H25: 48 | I25: pc | K25: =+J25*H25 -> 0
A26: Inner jacket stripping for coaxial cable | B26: Inner jacket stripping | C26: Schleuniger CS5500 | D26: place the cable in the machine head | E26: put cable away | F26: 0 | G26: 80 | H26: 12.4 | I26: pc | K26: =+J26*H26 -> 0 | L26: Manual
A27: Inner jacket stripping for coaxial cable | B27: Inner jacket full stripping | C27: Schleuniger CS6580 | D27: place the cable in the machine head | E27: put cable away | F27: 0 | G27: 10 | H27: 8.2 | K27: =+J27*H27 -> 0
B28: Inner jacket partial stripping | D28: place the cable in the machine head | E28: put cable away | F28: 0 | G28: 20 | H28: 7.7 | K28: =+J28*H28 -> 0
A29: Stripping the filler of multicore cable | B29: Stripping the filler of multicore cable | C29: manual work | D29: pick up the cable | E29: put cable away | F29: 80 | G29: 200 | H29: 25 | I29: pc | K29: =+J29*H29 -> 0 | L29: Manual
A30: Inner wire stripping for multicore cable | B30: Inner wire stripping for multicore cable | C30: Unistrip 2600 | D30: pick up the cable | E30: Cable released | F30: 0.5 mm² | G30: 6 mm² | H30: 8.9 | I30: pc | K30: =+J30*H30 -> 0 | L30: Manual
A31: Comb out braided shield | B31: Comb out braided shield | C31: Boewe 1005 | D31: place the cable in the tool | E31: put cable away | F31: 0 | G31: 30 | H31: 38.2 | I31: pc | K31: =+J31*H31 -> 0 | L31: Manual
A32: Clean dust after combing | B32: Cleaning cable (to remove the dust and dirt) | C32: manual work | D32: pick up the cable | E32: put cable away | H32: 8 | I32: pc | K32: =+J32*H32 -> 0 | L32: Manual
A33: Twisting shield | B33: Twisting shield | C33: Boewe 1003 | D33: place the cable in the tool | E33: put cable away | F33: 0 | G33: 30 | H33: 13 | I33: pc | K33: =+J33*H33 -> 0 | L33: Manual
A34: Cut the twisted shield | B34: Cut the twisted shield | C34: manual | D34: pick up the cable | E34: put cable away | H34: 28 | I34: pc | K34: =+J34*H34 -> 0 | L34: Manual
A35: Comb out braided shield of inner twisted wire (multicore) | B35: Comb out braided shield of inner twisted wire | C35: manual work | D35: pick up the cable | E35: Cable released | H35: 28 | I35: pc | K35: =+J35*H35 -> 0 | L35: Manual
A36: Open the shield | B36: Coaxial wires: Open the shield with hand tool , pick up the inner ferrul and place under the braided shield. Multicore wires: pick up inner ferrule and place over wire , open the shield and fold back over inner ferrule by hand | C36: hand tool | D36: pick up the cable | E36: shield opened | H36: 10 | I36: pc | K36: =+J36*H36 -> 0 | L36: Manual
A37: Apply outer ferrul over inner ferrule | B37: Pick up the outer ferrul, apply to the cable and move outer ferrule over the inner ferrul / terminal group | C37: hand tool | D37: pick up the ferrul | E37: ready for crimping | H37: 10 | I37: pc | K37: =+J37*H37 -> 0 | L37: Manual
A38: Apply loose piece terminal to wire | B38: Pick up and apply loose piece terminal (ring) to wire to cover all strands | C38: manual work | D38: pick up the loose piece | E38: put cable away | H38: 7.14 | I38: pc | K38: =+J38*H38 -> 0 | L38: Manual
A39: Apply loose piece terminal to wire in alubox | B39: Pick up and apply loose piece terminal (ring) to wire in alubox to cover all strands | C39: manual work | D39: pick up the loose piece | E39: put cable away | H39: 19.11 | I39: pc | K39: =+J39*H39 -> 0 | L39: Manual
A40: Place the alubox in support | B40: Pick up teh support and place the alubox | C40: manual work | D40: pick up the support | E40: alubox in the support | H40: 16 | I40: pc | K40: =+J40*H40 -> 0 | L40: Manual
A41: Place the support in the press | B41: Pick up and place the support in the press (for alubox, connector, housing to guarantee the accesories orientation) | C41: test holder | D41: pick up the alubox | E41: ready for crimping | H41: 7.04 | I41: pc | K41: =+J41*H41 -> 0 | L41: Manual
A42: Routing for terminal orientation | B42: Routing of cable in order to obtain correct orientation for crimping | C42: manual work | D42: pick up the cable | E42: ready for crimping | H42: 8.9 | I42: pc | K42: =+J42*H42 -> 0 | L42: Manual
...

Sheet FA Conns and wires
A2: FA - CONNECTORS AND WIRES
A3: BUILD CATEGORY | E3: ACTIVITY DESCRIPTION | I3: Standard Description | M3: Clock start | O3: Clock stop | Q3: GLOBAL SEC/PC | R3: UNIT | S3: Qty | T3: Total Time
A4: Build connectors to board | E4: Assemble connectors | I4: 1-6 way to V-pin | M4: Reach for connector | O4: Release connector after placing to V-pin | Q4: 1.7 | R4: pc | S4: 20 | T4: =+S4*Q4 -> 34 | U4: Semi-automatic
I5: >6, <40 way to connector holder NOTE: to be used also for connector with less than 6 ways when CRA or PFMEA recommendation / Customer request | M5: Reach for connector | O5: Release connector after placing to connector holder | Q5: 4 | R5: pc | S5: 9 | T5: =+S5*Q5 -> 36 | U5: Semi-automatic
I6: >= 40 way to connector holder / cable channel to the holder | M6: Reach for connector | O6: Release connector after placing to connector holder | Q6: 5.4 | R6: pc | S6: 5 | T6: =+S6*Q6 -> 27 | U6: Semi-automatic
A10: Manual coiling Cross section =< 4mm² | E10: 7501 - 8000 | I10: Get wire from the tray | N10: Coiled wire closed with re-usable material | O10: Coiling station to be used. Wires to be placed in horizontal trays. To close the coiled wire re-usable / recyclable material to be used. | Q10: 14.36 | R10: pc | T10: =+S10*Q10 -> 0 | U10: Automatic
E11: 8001 - 9000 | Q11: 15.31 | R11: pc | T11: =+S11*Q11 -> 0 | U11: Automatic
E12: 9001 - 10 000 | Q12: 17.2 | R12: pc | T12: =+S12*Q12 -> 0 | U12: Automatic
E13: 10 001 - 11 000 | Q13: 18.7 | R13: pc | T13: =+S13*Q13 -> 0 | U13: Automatic
E14: 11 001 - 12 000 | Q14: 20.4 | R14: pc | T14: =+S14*Q14 -> 0 | U14: Automatic
E15: 12 001 - 13 000 | Q15: 22.1 | R15: pc | T15: =+S15*Q15 -> 0 | U15: Automatic
E16: 13 001 - 14 000 | Q16: 23.8 | R16: pc | T16: =+S16*Q16 -> 0 | U16: Automatic
E17: 14 001 - 15 000 | Q17: 25.5 | R17: pc | T17: =+S17*Q17 -> 0 | U17: Automatic
E18: 15 001 - 16 000 | Q18: 27.2 | R18: pc | T18: =+S18*Q18 -> 0 | U18: Automatic
E19: 16 001 - 17 000 | Q19: 28.9 | R19: pc | T19: =+S19*Q19 -> 0 | U19: Automatic
E20: 17 001 - 18 000 | Q20: 30.6 | R20: pc | T20: =+S20*Q20 -> 0 | U20: Automatic
E21: 18 001 - 19 000 | Q21: 32.3 | R21: pc | T21: =+S21*Q21 -> 0 | U21: Automatic
T22: =+S22*Q22 -> 0
T23: =+S23*Q23 -> 0
T24: =+S24*Q24 -> 0
A26: Manual coiling Cross section > 4mm² < 11mm² To be used also for twisted wires, doubles, multiconductors, coaxial cables and antennas needs when total (sum of gages) cross section > than 3 mm² and length is more than 4 mt | E26: 4001 - 5000 | I26: Get wire from the tray | N26: Coiled wire closed with re-usable material | O26: Coiling station to be used. Wires to be placed in horizontal trays. To close the coiled wire re-usable / recyclable material to be used. | Q26: 10.5 | R26: pc | T26: =+S26*Q26 -> 0 | U26: Automatic
E27: 5001 - 6000 | Q27: 12.6 | R27: pc | T27: =+S27*Q27 -> 0 | U27: Automatic
E28: 6001 - 7000 | Q28: 14.7 | R28: pc | T28: =+S28*Q28 -> 0 | U28: Automatic
E29: 7001 - 8000 | Q29: 15.2 | R29: pc | T29: =+S29*Q29 -> 0 | U29: Automatic
E30: 8001 - 9000 | Q30: 17.1 | R30: pc | T30: =+S30*Q30 -> 0 | U30: Automatic
E31: 9001 - 10 000 | Q31: 19 | R31: pc | T31: =+S31*Q31 -> 0 | U31: Automatic
E32: 10 001 - 11 000 | Q32: 20.9 | R32: pc | T32: =+S32*Q32 -> 0 | U32: Automatic
E33: 11 001 - 11 000 | Q33: 22.8 | R33: pc | T33: =+S33*Q33 -> 0 | U33: Automatic
E34: 12 001 - 13 000 | Q34: 24.7 | R34: pc | T34: =+S34*Q34 -> 0 | U34: Automatic
E35: 13 001 - 14 000 | Q35: 26.6 | R35: pc | T35: =+S35*Q35 -> 0 | U35: Automatic
E36: 14 001 - 15 000 | Q36: 28.5 | R36: pc | T36: =+S36*Q36 -> 0 | U36: Automatic
E37: 15 001 - 16 000 | Q37: 30.4 | R37: pc | T37: =+S37*Q37 -> 0 | U37: Automatic
E38: 16 001 - 17 000 | Q38: 32.3 | R38: pc | T38: =+S38*Q38 -> 0 | U38: Automatic
... E40: 18 001 - 19 000 | Q40: 36.1 | R40: pc | T40: =+S40*Q40 -> 0 | U40: Automatic
T41: =+S41*Q41 -> 0
T42: =+S42*Q42 -> 0
T43: =+S43*Q43 -> 0
A45: Get coiled wire | E45: Get coiled wire (antenna, twist, double, multiconductor, coaxial etc) for plugging | I45: Pick up the coiled wire, remove the ball fix, ready for plug | N45: Pick up the coiled wire | O45: Wire ready for plugging | Q45: 4.33 | R45: pc | T45: =+S45*Q45 -> 0 | U45: Automatic
A47: Get and Route wires ( get and remove wires from rack operation to be used only for uncoiled wires) | E47: Get and remove wires from rack | I47: up to 1000 mm | M47: Reach for wire | O47: Wire in hand ready for first plug | Q47: 1.625 | R47: pc | S47: 52 | T47: =+S47*Q47 -> 84.5 | U47: Semi-auto
E48: Route wires on board | I48: up to 1000 mm | M48: Wire in hand after first plug | O48: Wire in hand ready for second plug | Q48: 1.46 | R48: pc | S48: 56 | T48: =+S48*Q48 -> 81.76 | U48: Semi-auto
...

Sheet FA Taping
A1: FA - TAPING
A2: BUILD CATEGORY | C2: ACTIVITY DESCRIPTION | D2: Standard Description | E2: CLOCK START | F2: CLOCK STOP | G2: GLOBAL SEC/PC | H2: UNIT | I2: Qty | J2: Total Time
A3: Automatic taping | C3: Load/unload wires/harness to machine | D3: Does not include any taping - only start of tape on wires | E3: Reach for wires | F3: Release taped wires on rack | G3: 8.5 | H3: pc | J3: =+I3*G3 -> 0 | K3: Manual
C4: Machine Taping time (Secs. /mm) | D4: Ondal or similar | E4: Machine starts taping | F4: Machine stops taping at pre-set dimension | G4: 0.009 | H4: mm | J4: =+I4*G4 -> 0 | K4: Manual
A6: Manual taping | C6: Apply spot tape-PVC/Textile/Cloth | D6: Single spot tape. | E6: Reach for tape | F6: Release taped branch | G6: 4.2 | H6: pc | I6: 9 | J6: =+I6*G6 -> 37.8 | K6: Manual
D7: Close conduit with tape | G7: 6.2 | H7: pc | I7: 2 | J7: =+I7*G7 -> 12.4 | K7: Manual
D8: Tape under and tape on clip (L) | G8: 6.2 | H8: pc | J8: =+I8*G8 -> 0 | K8: Manual
C9: Tape on body clip / clamp | D9: Locate & hold clip / clamp over branch | E9: Get clip / clamp | F9: Release clip / clamp on branch | G9: 3 | H9: pc | J9: =+I9*G9 -> 0 | K9: Automatic
C10: Apply double spot tape-PVC/Textile/Cloth | D10: Double spot tape. To be used also for tape on body clip / diaper. | E10: Reach for tape | F10: Release taped branch | G10: 7.2 | H10: pc | J10: =+I10*G10 -> 0 | K10: Manual
D11: Secure grommets to branch with tape. | G11: 7.2 | J11: =+I11*G11 -> 0 | K11: Manual
D12: Tape cable channel closed operation | G12: 7.2 | H12: pc | I12: 1 | J12: =+I12*G12 -> 7.2 | K12: Manual
D13: Tape under conduit end and close conduit with tape. To secure covering. Time to be used also to fix coflex tube | G13: 8.8 | H13: pc | I13: 70 | J13: =+I13*G13 -> 616 | K13: Manual
D14: Tape under and double tape on clip | G14: 8.8 | H14: pc | J14: =+I14*G14 -> 0 | K14: Manual
C15: Note: For automatic calculation on GSD; If branch length available in GSD multiply it by SEC/PC otherwise, as approach multiply SEC/PC by tape length/1.5 for spiral tapes and tape length/2 for others.
A16: Manual taping Overlape/Spiral | C16: Get and start Tape | D16: Apply to PVC/Textile / felt tape for overlape/spiral | E16: Get tape | F16: taping started over branch | G16: 5 | H16: pc | I16: 9 | J16: =(I16-L16)*G16 -> 45 | K16: Manual | M16: =I16-L16 -> 9
A17: Manual taping | C17: Overlap taping /double overlap / full - PVC | D17: Tape width = 16 mm | E17: Hold tape | F17: Split tape | G17: 0.052 | H17: mm | J17: =+I17*G17 -> 0 | K17: Manual
D18: Tape width = 19 mm | E18: Hold tape | F18: Split tape | G18: 0.036 | H18: mm | I18: 915 | J18: =+I18*G18 -> 32.94 | K18: Manual
D19: Tape width = 25 mm | E19: Hold tape | F19: Split tape | G19: 0.032 | H19: mm | J19: =+I19*G19 -> 0 | K19: Manual
D20: Tape width = 32 mm | E20: Hold tape | F20: Split tape | G20: 0.028 | H20: mm | J20: =+I20*G20 -> 0 | K20: Manual
C21: Overlap taping / double overlap / full -Textile/Cloth / Loom | D21: Tape width = 19 mm | E21: Hold tape | F21: Split tape | G21: 0.044 | H21: mm | I21: 245 | J21: =+I21*G21 -> 10.78 | K21: Manual
D22: Tape width = 19 mm when overlap equal or over 50% requested by Customer | E22: Hold tape | F22: Split tape | G22: 0.058 | H22: mm | J22: =+I22*G22 -> 0 | K22: Manual
D23: Tape width = 25 mm | E23: Hold tape | F23: Split tape | G23: 0.038 | H23: mm | J23: =+I23*G23 -> 0 | K23: Manual
D24: Tape width = 25 mm when overlap equal or over 50% requested by Customer | E24: Hold tape | F24: Split tape | G24: 0.051 | H24: mm | J24: =+I24*G24 -> 0
D25: Tape width = 32 mm | E25: Hold tape | F25: Split tape | G25: 0.03 | H25: mm | J25: =+I25*G25 -> 0 | K25: Manual
C26: Overlap Taping / double overlap / full - Felt | D26: Tape width = 19 mm | E26: Hold tape | F26: Split tape | G26: 0.049 | H26: mm | J26: =+I26*G26 -> 0 | K26: Manual
D27: Tape width = 25 mm | E27: Hold tape | F27: Split tape | G27: 0.039 | H27: mm | J27: =+I27*G27 -> 0 | K27: Manual
D28: Tape width = 38 mm | E28: Hold tape | F28: Split tape | G28: 0.027 | H28: mm | J28: =+I28*G28 -> 0
D29: Tape width = 38 mm mm when overlap equal or over 50% requested by Customer | E29: Hold tape | F29: Split tape | G29: 0.039 | H29: mm | J29: =+I29*G29 -> 0 | K29: Manual
C30: Overlap Taping-Foam | D30: Per mm | E30: Hold tape | F30: Split tape | G30: 0.08 | H30: mm | J30: =+I30*G30 -> 0 | K30: Manual
C31: Overlap / Solid taping -- cloth (burrito) | D31: Tape widt = 35 mm | E31: Hold tape | F31: Split tape | G31: 0.048 | H31: mm | J31: =+I31*G31 -> 0
C32: Overlap / Solid taping -- cloth (burrito) | D32: Tape widt > 35 mm | E32: Hold tape | F32: Split tape | G32: 0.06 | H32: mm | J32: =+I32*G32 -> 0 | K32: Manual
C33: Overlap Taping-Aluminized Film / moon tape (heat reflective) | D33: Tape width 32 mm | E33: Hold tape | F33: Split tape | G33: 0.04 | H33: mm | J33: =+I33*G33 -> 0 | K33: Manual
D34: Tape width 25 mm | E34: Hold tape | F34: Split tape | G34: 0.045 | H34: mm | J34: =+I34*G34 -> 0 | K34: Manual
A37: Manual taping | C37: Spiral Taping-PVC | D37: Tape width = 9 mm | E37: Hold tape | F37: Split tape | G37: 0.029 | H37: mm | J37: =+I37*G37 -> 0 | K37: Manual
D38: Tape width = 16 mm | E38: Hold tape | F38: Split tape | G38: 0.025 | H38: mm | J38: =+I38*G38 -> 0 | K38: Manual
D39: Tape width = 19 mm | E39: Hold tape | F39: Split tape | G39: 0.02 | H39: mm | I39: 595 | J39: =+I39*G39 -> 11.9 | K39: Manual
D40: Tape width = 25 mm | E40: Hold tape | F40: Split tape | G40: 0.015 | H40: mm | J40: =+I40*G40 -> 0 | K40: Manual
D41: Tape width = 32 mm | E41: Hold tape | F41: Split tape | G41: 0.017 | H41: mm | J41: =+I41*G41 -> 0 | K41: Manual
C42: Spiral taping-Textile/Cloth | D42: Tape width = 9 mm | E42: Hold tape | F42: Split tape | G42: 0.032 | H42: mm | J42: =+I42*G42 -> 0 | K42: Manual
D43: Tape width = 12.5 mm | E43: Hold tape | F43: Split tape | G43: 0.026 | H43: mm | J43: =+I43*G43 -> 0 | K43: Manual
...

Sheet FA Miscellaneos
A1: MISCELLANEOUS
A2: BUILD CATEGORY | C2: ACTIVITY DESCRIPTION | E2: Standard Description | F2: CLOCK START | G2: CLOCK STOP | H2: GLOBAL SEC/PC | I2: UNIT | J2: QTY | K2: Total Time
A3: MISC. ASSEMBLY | C3: Apply secondary locks and covers to connectors / grommet | E3: Loose piece secondary Locks/Covers/Combs / Inserts / hexagonal lock | F3: Get component | G3: Release connector | H3: 4.6 | I3: pc | J3: 11 | K3: =+J3*H3 -> 50.6 | L3: Semi-automatic
E4: Close secondary locks/covers which are attached to connectors | F4: Reach for connector | G4: Release connector | H4: 1.49 | I4: pc | J4: 22 | K4: =+J4*H4 -> 32.78 | L4: Automatic
E5: Large covers for >40 way connectors NOTE FOR HV PROD: apply 2 piece cover to connector | F5: Get component | G5: Release connector | H5: 15.49 | I5: pc | J5: 3 | K5: =+J5*H5 -> 46.47 | L5: Semi-automatic
C6: Apply terminal stabilizer to connector | E6: Assembly terminal stabilizer / retainer / mylar into connector | F6: Get component | G6: Release connector | H6: 6 | I6: pc | K6: =+J6*H6 -> 0 | L6: Automatic
C7: Apply vacuum / washer fluid hose | E7: Get hose and route on board T- to be applied to hoses up to 3 m | F7: Get hose | G7: Release hose | H7: 6 | I7: pc | K7: =+J7*H7 -> 0 | L7: Automatic
C8: get and apply spiral tube | E8: per mm | F8: Reach for spiral tube | G8: Release branch | H8: 0.063 | I8: mm | K8: =+J8*H8 -> 0 | L8: Automatic
A9: Torque | C9: Get harness from transportation system | E9: per harness | F9: Reach for the harness | G9: start of fusebox scanning | H9: 6 | I9: pc | K9: =+J9*H9 -> 0
C10: Scan manifest/ barcode label | E10: per harness | F10: Reach for the scanner | G10: Scanner putting down | H10: 2.8 | I10: pc | K10: =+J10*H10 -> 0
C11: Fusebox scanning (if requested by Customer) | E11: per fusebox | F11: reach for the scanner | G11: Scanner putting down | H11: 2.8 | I11: pc | K11: =+J11*H11 -> 0
C12: Fusebox placing into holder | E12: per fusebox | F12: Scanner putting down | G12: Fusebox fixed into holder | H12: 5 | I12: pc | K12: =+J12*H12 -> 0
C13: Get and Apply Screw (machine or self-tapping screw) | E13: per Screw | F13: Reach for Screw | G13: Release Screw | H13: 6.5 | I13: pc | K13: =+J13*H13 -> 0 | L13: Automatic
C14: Get and apply BOLT With/Without COVER + Tightening | E14: Per Piece | F14: Reach for bolt and cover | G14: Release connector/ring terminal after apply the nut/screw | H14: 10 | I14: pc | K14: =+J14*H14 -> 0 | L14: Automatic
C15: BOLT CONN PROCESS | E15: Per Piece | F15: Reach for screw | G15: Release connector after apply the screw | H15: 8.8 | I15: pc | K15: =+J15*H15 -> 0 | L15: Automatic
C16: Get and apply NUT TO BOLT + Tightening | E16: Per Piece | F16: Reach for nut | G16: Release connector/ring terminal after apply the nut/screw | H16: 15 | I16: pc | K16: =+J16*H16 -> 0
C17: Remove fusebox from holder after finished test | E17: per fusebox | F17: Reach for the fusebox | G17: Fusebox on the transportation system | H17: 4 | I17: pc | K17: =+J17*H17 -> 0
A18: GET SUPPORT AND ASSEMBLY CONNECTOR | C18: Get support and assembly connector to support | E18: Get Support | F18: Get Support | G18: Release support | H18: 4.2 | I18: pc | K18: =+J18*H18 -> 0 | L18: Manual
E19: Assembly Conn to Support | F19: Get component | G19: Release connector | H19: 3.6 | I19: pc | K19: =+J19*H19 -> 0 | L19: Manual
A20: GET , APPLY AND FIX COFLEX TUBE | C20: For Coflex Tube the time included To get, Apply and adjust tubes in right position | F20: Get Coflex tube | G20: Release tube | H20: 6.05 | I20: pc | K20: =+J20*H20 -> 0 | L20: Automatic
F21: Reach coflex tube | G21: release branch after finish application | H21: 0.052 | I21: mm | K21: =+J21*H21 -> 0 | L21: Automatic
A22: GET , APPLY AND FIX KNITTED UNSLITTED TUBE ( GAINE TRESSEE ) | F22: GET , APPLY AND FIX | H22: 20.5 | I22: pc | K22: =+J22*H22 -> 0 | L22: Automatic
A23: GET AND APPLY LOCATWRAP TUBE | F23: GET AND APPLY | H23: 0.073 | I23: mm | K23: =+J23*H23 -> 0 | L23: Automatic
A24: Raidisseur Application inside Harness unflexible tube | F24: GET AND APPLY | H24: 0.01 | I24: mm | K24: =+J24*H24 -> 0 | L24: Manual
A25: Conduits and Tubes SEALED / UNSEALED WIRES | C25: Get closed (unslit) conduits and tubes - sealed / unsealed wires | E25: Per Piece | F25: Get conduit/tube | G25: Reach for branch | H25: 5.941 | I25: pc | J25: 9 | K25: =+J25*H25 -> 53.469 | L25: Automatic
C26: Apply closed (unslit) conduits and tubes - sealed / unsealed wires | E26: Per mm | F26: Start Apply | G26: Release branch | H26: 0.01213 | I26: mm | J26: 1125 | K26: =+J26*H26 -> 13.64625 | L26: Automatic
C27: Insert wires through closed conduits/tubes 0mm - 1500mm NOTE: group of wires (twists, multiconductors etc) to be considered as 1 wire | E27: per each wire | F27: Reach for wire | G27: Release branch | H27: 2.595 | I27: pc | J27: 39 | K27: =+J27*H27 -> 101.205 | L27: Automatic
C28: Insert wires through closed conduits/tubes 1501mm - 6000mm NOTE: group of wires (twists, multiconductors etc) to be considered as 1 wire | E28: per each wire | F28: Reach for wire | G28: Release branch | H28: 6.48 | I28: pc | K28: =+J28*H28 -> 0 | L28: Automatic
A29: Pass wires in tubes | C29: M-SPEC: M 3558 ... LENGHT > 250mm or pass wires UL3123 M - SPEC: M3419... IN TUBES UNSLIT | E29: Time additional PER TUBE | F29: Reach for tube | G29: Release the branch | H29: 31.99 | I29: pc | K29: =+J29*H29 -> 0 | L29: Automatic
A30: Tubes | C30: Glue PVC tubes (glue / sealing tube) | E30: Per application (considering two tubes) | F30: Get hand glue applicator | G30: Release the glued tubes | H30: 15.81 | I30: Per application | K30: =+J30*H30 -> 0 | L30: Manual
E31: Time for additional tube | F31: Get hand glue applicator | G31: Release the glued tubes | H31: 6.108 | I31: pc | K31: =+J31*H31 -> 0 | L31: Manual
C32: Joint fuel tube with sleeve tube | E32: Each group | F32: Get tube | G32: Release tube | H32: 26.44 | I32: pc | K32: =+J32*H32 -> 0 | L32: Automatic
C33: Insert Tube Inside Other Tube | E33: Time per tube / This Time includes Taping Tubes | F33: Get tube | G33: Release tube | H33: 25.002 | I33: pc | K33: =+J33*H33 -> 0 | L33: Manual
A34: Conduits and Tubes | C34: get and start apply slit PVC & braid tubes & conduits (usage of supporting tool is manufacturing standard) | E34: per mm, only get and start over branch | F34: Get tube/conduit | G34: Tube/conduit started over branch | H34: 4.009 | I34: pc | J34: 40 | K34: =+J34*H34 -> 160.36 | L34: Automatic
C35: Apply slit PVC & braid tubes & conduits | E35: per mm, slide conduits over wires (slit convoluted conduit) | F35: Conduit started over branch | G35: Release branch after conduit application | H35: 0.009 | I35: mm | J35: 5530 | K35: =+J35*H35 -> 49.77 | L35: Automatic
E36: per mm, slide PVC & braid tubes over wires (slit PVC & braid tubes and conduit overlap) | F36: Tube started over branch | G36: Release branch after tube application | H36: 0.011 | I36: mm | J36: 714 | K36: =+J36*H36 -> 7.854 | L36: Automatic
C37: Punch Conduit with gun (moon shape) | E37: When a conduit goes through a breakout | F37: Reach for spiral tube | G37: Release branch | H37: 9.9 | I37: Per application | K37: =+J37*H37 -> 0 | L37: Manual
A38: Conduits | C38: apply conduit fittings | E38: apply "end" fitting to conduit - single branch | F38: Reach for "end" piece | G38: Release branch | H38: 5.048 | I38: pc | J38: 2 | K38: =+J38*H38 -> 10.096 | L38: Automatic
E39: Apply conduit clip | H39: 4.2 | I39: pc | J39: 1 | K39: =+J39*H39 -> 4.2 | L39: Manual
E40: apply "T" , "Y", "L" and multi inline fitting over conduits | F40: Reach for the piece | G40: Release branch | H40: 9.798 | I40: pc | K40: =+J40*H40 -> 0 | L40: Automatic
...
